<?xml version="1.0"?>
<!-- Revolute-Revolute Manipulator -->
<robot name="linemod_template" xmlns:xacro="http://www.ros.org/wiki/xacro">

  <!-- Constants for robot dimensions -->
  <xacro:property name="PI" value="3.1415926535897931"/>
  <xacro:property name="mass" value="1" /> <!-- arbitrary value for mass -->
  <xacro:property name="width" value="0.1" /> <!-- Square dimensions (widthxwidth) of beams -->
  <xacro:property name="height1" value="2" /> <!-- Link 1 -->
  <xacro:property name="height2" value="1" /> <!-- Link 2 -->
  <xacro:property name="height3" value="1" /> <!-- Link 3 -->
  <xacro:property name="camera_link" value="0.05" /> <!-- Size of square 'camera' box -->
  <xacro:property name="axel_offset" value="0.05" /> <!-- Space btw top of beam and the each joint -->

  <!-- Import all Gazebo-customization elements, including Gazebo colors -->
  <xacro:include filename="$(find linemod_template_description)/urdf/linemod_template.gazebo" />
  <!-- <xacro:include filename="$(find higa_kinect_description)/urdf/higa_kinect.xacro" /> -->

  <!-- Used for fixing robot to Gazebo 'base_link' -->
  <link name="world"/>
  <!-- <link name="camera_depth_frame"/> -->

  <!-- object -->
  <joint name="mesh_model_joint" type="floating">
    <axis xyz="0 0 0" />
    <!-- for object1 -->
    <!-- <origin xyz="-0.06 -0.075 -0.08" rpy="0 0 0"/> -->
    <!-- for object2 -->
    <origin xyz="-0.12 -0.005 -0.04" rpy="0 0 0"/>
    <!-- for mugcup -->
    <!-- <origin xyz="-0.04 -0.04 -0.04" rpy="0 0 0"/> -->
    <parent link="world"/>
    <!-- <parent link="camera_depth_frame"/> -->
    <child link="mesh_model_link"/>
  </joint>

  <link name="mesh_model_link">
    <collision>
      <origin xyz="0.1 0.1 0" rpy="0 0 0"/>
      <geometry>
	<box size="0.1 0.1 0.1"/>
      </geometry>
    </collision>
    <visual>
      <geometry>
	<mesh filename="package://linemod_template_description/meshes/object1.dae"/>
      </geometry>
    </visual>
    <inertial>
      <mass value="1e-5" />
      <origin xyz="0.1 0.1 0" rpy="0 0 0"/>
      <inertia ixx="1e-6" ixy="0" ixz="0" iyy="1e-6" iyz="0" izz="1e-6" />
    </inertial>
  </link>
</robot>
