<?xml version="1.0" ?>
<!-- =================================================================================== -->
<!-- |    This document was autogenerated by xacro from linemod_template.xacro         | -->
<!-- |    EDITING THIS FILE BY HAND IS NOT RECOMMENDED                                 | -->
<!-- =================================================================================== -->
<!-- Revolute-Revolute Manipulator -->
<robot name="linemod_template" xmlns:xacro="http://www.ros.org/wiki/xacro">
  <!-- Space btw top of beam and the each joint -->
  <!-- ros_control plugin -->
  <gazebo>
    <plugin filename="libgazebo_ros_control.so" name="gazebo_ros_control">
      <robotNamespace>/linemod_template</robotNamespace>
      <robotSimType>gazebo_ros_control/DefaultRobotHWSim</robotSimType>
    </plugin>
  </gazebo>
  <gazebo reference="mesh_model_link">
  </gazebo>
  <!-- <xacro:include filename="$(find higa_kinect_description)/urdf/higa_kinect.xacro" /> -->
  <!-- Used for fixing robot to Gazebo 'base_link' -->
  <link name="world"/>
  <!-- <link name="camera_depth_frame"/> -->
  <!-- object -->
  <joint name="mesh_model_joint" type="floating">
    <axis xyz="0 0 0"/>
    <!-- for mugcup (object1) -->
    <origin xyz="-0.06 -0.075 -0.08" rpy="0 0 0"/>

    <!-- for origin -->
    <!-- <origin rpy="0 0 0" xyz="0 0 0"/> -->

    <parent link="world"/>
    <!-- <parent link="camera_depth_frame"/> -->
    <child link="mesh_model_link"/>
  </joint>
  <link name="mesh_model_link">
    <collision>
      <origin rpy="0 0 0" xyz="0.1 0.1 0"/>
      <geometry>
        <box size="0.1 0.1 0.1"/>
      </geometry>
    </collision>
    <visual>
      <geometry>
        <mesh filename="package://linemod_template_description/meshes/object1.dae"/>
      </geometry>
    </visual>
    <inertial>
      <mass value="1e-5"/>
      <origin rpy="0 0 0" xyz="0.1 0.1 0"/>
      <inertia ixx="1e-6" ixy="0" ixz="0" iyy="1e-6" iyz="0" izz="1e-6"/>
    </inertial>
  </link>
</robot>
